2025-04-11 22:52:29,230 - DEBUG - Starting authorization phase
2025-04-11 22:52:29,231 - DEBUG - The provided initial strategy is mysql_native_password
2025-04-11 22:52:29,231 - INFO - package: mysql.connector.plugins
2025-04-11 22:52:29,231 - INFO - plugin_name: mysql_native_password
2025-04-11 22:52:29,233 - INFO - AUTHENTICATION_PLUGIN_CLASS: MySQLNativePasswordAuthPlugin
2025-04-11 22:52:29,241 - DEBUG - mysql_native_password completed succesfully
2025-04-11 22:52:29,270 - INFO - Database connection established
2025-04-11 22:52:29,284 - INFO - Database tables initialized
2025-04-11 22:52:29,288 - INFO - Twilio client initialized successfully
2025-04-11 22:52:29,294 - INFO - Serving on http://0.0.0.0:5001
2025-04-11 22:52:29,296 - DEBUG - Using selector: SelectSelector
2025-04-11 22:52:29,307 - INFO - Start watching changes
2025-04-11 22:52:29,310 - INFO - Start detecting changes
2025-04-11 22:52:38,820 - INFO - C:\xampp\htdocs\Inbox\tripglide\backend\login.py modified; restarting server
2025-04-11 22:53:11,647 - DEBUG - Starting authorization phase
2025-04-11 22:53:11,648 - DEBUG - The provided initial strategy is mysql_native_password
2025-04-11 22:53:11,648 - INFO - package: mysql.connector.plugins
2025-04-11 22:53:11,648 - INFO - plugin_name: mysql_native_password
2025-04-11 22:53:11,649 - INFO - AUTHENTICATION_PLUGIN_CLASS: MySQLNativePasswordAuthPlugin
2025-04-11 22:53:11,650 - DEBUG - mysql_native_password completed succesfully
2025-04-11 22:53:11,651 - INFO - Database connection established
2025-04-11 22:53:11,652 - INFO - Database tables initialized
2025-04-11 22:53:11,653 - INFO - Twilio client initialized successfully
2025-04-11 22:53:11,655 - INFO - Serving on http://0.0.0.0:5001
2025-04-11 22:53:11,656 - DEBUG - Using selector: SelectSelector
2025-04-11 22:53:11,661 - INFO - Start watching changes
2025-04-11 22:53:11,661 - INFO - Start detecting changes
2025-04-11 22:53:16,460 - ERROR - Database error in profile: Unread result found
2025-04-11 22:53:16,462 - ERROR - 500 GET /api/profile?identifier=jaimilkothari2003@gmail.com (127.0.0.1) 62.41ms
2025-04-11 22:53:16,466 - DEBUG - Starting authorization phase
2025-04-11 22:53:16,467 - DEBUG - The provided initial strategy is mysql_native_password
2025-04-11 22:53:16,467 - DEBUG - mysql_native_password completed succesfully
2025-04-11 22:53:16,468 - ERROR - Exception on /api/flight_bookings [GET]
Traceback (most recent call last):
  File "C:\Users\JAIMIL KOTHARI\AppData\Roaming\Python\Python313\site-packages\mysql\connector\abstracts.py", line 1592, in reconnect
    self.connect()
    ~~~~~~~~~~~~^^
  File "C:\Users\JAIMIL KOTHARI\AppData\Roaming\Python\Python313\site-packages\mysql\connector\abstracts.py", line 1541, in connect
    self._post_connection()
    ~~~~~~~~~~~~~~~~~~~~~^^
  File "C:\Users\JAIMIL KOTHARI\AppData\Roaming\Python\Python313\site-packages\mysql\connector\abstracts.py", line 1481, in _post_connection
    self.set_charset_collation(charset=self._charset_id)
    ~~~~~~~~~~~~~~~~~~~~~~~~~~^^^^^^^^^^^^^^^^^^^^^^^^^^
  File "C:\Users\JAIMIL KOTHARI\AppData\Roaming\Python\Python313\site-packages\mysql\connector\abstracts.py", line 1366, in set_charset_collation
    self._execute_query(f"SET NAMES '{charset_name}' COLLATE '{collation_name}'")
    ~~~~~~~~~~~~~~~~~~~^^^^^^^^^^^^^^^^^^^^^^^^^^^^^^^^^^^^^^^^^^^^^^^^^^^^^^^^^^
  File "C:\Users\JAIMIL KOTHARI\AppData\Roaming\Python\Python313\site-packages\mysql\connector\connection.py", line 1430, in _execute_query
    self.handle_unread_result()
    ~~~~~~~~~~~~~~~~~~~~~~~~~^^
  File "C:\Users\JAIMIL KOTHARI\AppData\Roaming\Python\Python313\site-packages\mysql\connector\connection.py", line 1740, in handle_unread_result
    raise InternalError("Unread result found")
mysql.connector.errors.InternalError: Unread result found

The above exception was the direct cause of the following exception:

Traceback (most recent call last):
  File "C:\Users\JAIMIL KOTHARI\AppData\Roaming\Python\Python313\site-packages\flask\app.py", line 1511, in wsgi_app
    response = self.full_dispatch_request()
  File "C:\Users\JAIMIL KOTHARI\AppData\Roaming\Python\Python313\site-packages\flask\app.py", line 919, in full_dispatch_request
    rv = self.handle_user_exception(e)
  File "C:\Users\JAIMIL KOTHARI\AppData\Roaming\Python\Python313\site-packages\flask_cors\extension.py", line 176, in wrapped_function
    return cors_after_request(app.make_response(f(*args, **kwargs)))
                                                ~^^^^^^^^^^^^^^^^^
  File "C:\Users\JAIMIL KOTHARI\AppData\Roaming\Python\Python313\site-packages\flask\app.py", line 917, in full_dispatch_request
    rv = self.dispatch_request()
  File "C:\Users\JAIMIL KOTHARI\AppData\Roaming\Python\Python313\site-packages\flask\app.py", line 902, in dispatch_request
    return self.ensure_sync(self.view_functions[rule.endpoint])(**view_args)  # type: ignore[no-any-return]
           ~~~~~~~~~~~~~~~~~~~~~~~~~~~~~~~~~~~~~~~~~~~~~~~~~~~~^^^^^^^^^^^^^
  File "C:\xampp\htdocs\Inbox\tripglide\backend\login.py", line 384, in flight_bookings
    db.reconnect()  # Attempt to reconnect if disconnected
    ~~~~~~~~~~~~^^
  File "C:\Users\JAIMIL KOTHARI\AppData\Roaming\Python\Python313\site-packages\mysql\connector\abstracts.py", line 1601, in reconnect
    raise InterfaceError(msg) from err
mysql.connector.errors.InterfaceError: Can not reconnect to MySQL after 1 attempt(s): Unread result found
2025-04-11 22:53:16,629 - ERROR - 500 GET /api/flight_bookings?user_id=44 (127.0.0.1) 229.19ms
2025-04-11 22:53:16,635 - DEBUG - Starting authorization phase
2025-04-11 22:53:16,635 - DEBUG - The provided initial strategy is mysql_native_password
2025-04-11 22:53:16,636 - DEBUG - mysql_native_password completed succesfully
2025-04-11 22:53:16,636 - ERROR - Exception on /api/profile [GET]
Traceback (most recent call last):
  File "C:\Users\JAIMIL KOTHARI\AppData\Roaming\Python\Python313\site-packages\mysql\connector\abstracts.py", line 1592, in reconnect
    self.connect()
    ~~~~~~~~~~~~^^
  File "C:\Users\JAIMIL KOTHARI\AppData\Roaming\Python\Python313\site-packages\mysql\connector\abstracts.py", line 1541, in connect
    self._post_connection()
    ~~~~~~~~~~~~~~~~~~~~~^^
  File "C:\Users\JAIMIL KOTHARI\AppData\Roaming\Python\Python313\site-packages\mysql\connector\abstracts.py", line 1481, in _post_connection
    self.set_charset_collation(charset=self._charset_id)
    ~~~~~~~~~~~~~~~~~~~~~~~~~~^^^^^^^^^^^^^^^^^^^^^^^^^^
  File "C:\Users\JAIMIL KOTHARI\AppData\Roaming\Python\Python313\site-packages\mysql\connector\abstracts.py", line 1366, in set_charset_collation
    self._execute_query(f"SET NAMES '{charset_name}' COLLATE '{collation_name}'")
    ~~~~~~~~~~~~~~~~~~~^^^^^^^^^^^^^^^^^^^^^^^^^^^^^^^^^^^^^^^^^^^^^^^^^^^^^^^^^^
  File "C:\Users\JAIMIL KOTHARI\AppData\Roaming\Python\Python313\site-packages\mysql\connector\connection.py", line 1430, in _execute_query
    self.handle_unread_result()
    ~~~~~~~~~~~~~~~~~~~~~~~~~^^
  File "C:\Users\JAIMIL KOTHARI\AppData\Roaming\Python\Python313\site-packages\mysql\connector\connection.py", line 1740, in handle_unread_result
    raise InternalError("Unread result found")
mysql.connector.errors.InternalError: Unread result found

The above exception was the direct cause of the following exception:

Traceback (most recent call last):
  File "C:\Users\JAIMIL KOTHARI\AppData\Roaming\Python\Python313\site-packages\flask\app.py", line 1511, in wsgi_app
    response = self.full_dispatch_request()
  File "C:\Users\JAIMIL KOTHARI\AppData\Roaming\Python\Python313\site-packages\flask\app.py", line 919, in full_dispatch_request
    rv = self.handle_user_exception(e)
  File "C:\Users\JAIMIL KOTHARI\AppData\Roaming\Python\Python313\site-packages\flask_cors\extension.py", line 176, in wrapped_function
    return cors_after_request(app.make_response(f(*args, **kwargs)))
                                                ~^^^^^^^^^^^^^^^^^
  File "C:\Users\JAIMIL KOTHARI\AppData\Roaming\Python\Python313\site-packages\flask\app.py", line 917, in full_dispatch_request
    rv = self.dispatch_request()
  File "C:\Users\JAIMIL KOTHARI\AppData\Roaming\Python\Python313\site-packages\flask\app.py", line 902, in dispatch_request
    return self.ensure_sync(self.view_functions[rule.endpoint])(**view_args)  # type: ignore[no-any-return]
           ~~~~~~~~~~~~~~~~~~~~~~~~~~~~~~~~~~~~~~~~~~~~~~~~~~~~^^^^^^^^^^^^^
  File "C:\xampp\htdocs\Inbox\tripglide\backend\login.py", line 299, in profile
    db.reconnect()  # Attempt to reconnect if disconnected
    ~~~~~~~~~~~~^^
  File "C:\Users\JAIMIL KOTHARI\AppData\Roaming\Python\Python313\site-packages\mysql\connector\abstracts.py", line 1601, in reconnect
    raise InterfaceError(msg) from err
mysql.connector.errors.InterfaceError: Can not reconnect to MySQL after 1 attempt(s): Unread result found
2025-04-11 22:53:16,643 - ERROR - 500 GET /api/profile?identifier=jaimilkothari2003@gmail.com (127.0.0.1) 12.53ms
2025-04-11 22:53:16,655 - DEBUG - Starting authorization phase
2025-04-11 22:53:16,656 - DEBUG - The provided initial strategy is mysql_native_password
2025-04-11 22:53:16,659 - DEBUG - mysql_native_password completed succesfully
2025-04-11 22:53:16,660 - ERROR - Exception on /api/flight_bookings [GET]
Traceback (most recent call last):
  File "C:\Users\JAIMIL KOTHARI\AppData\Roaming\Python\Python313\site-packages\mysql\connector\abstracts.py", line 1592, in reconnect
    self.connect()
    ~~~~~~~~~~~~^^
  File "C:\Users\JAIMIL KOTHARI\AppData\Roaming\Python\Python313\site-packages\mysql\connector\abstracts.py", line 1541, in connect
    self._post_connection()
    ~~~~~~~~~~~~~~~~~~~~~^^
  File "C:\Users\JAIMIL KOTHARI\AppData\Roaming\Python\Python313\site-packages\mysql\connector\abstracts.py", line 1481, in _post_connection
    self.set_charset_collation(charset=self._charset_id)
    ~~~~~~~~~~~~~~~~~~~~~~~~~~^^^^^^^^^^^^^^^^^^^^^^^^^^
  File "C:\Users\JAIMIL KOTHARI\AppData\Roaming\Python\Python313\site-packages\mysql\connector\abstracts.py", line 1366, in set_charset_collation
    self._execute_query(f"SET NAMES '{charset_name}' COLLATE '{collation_name}'")
    ~~~~~~~~~~~~~~~~~~~^^^^^^^^^^^^^^^^^^^^^^^^^^^^^^^^^^^^^^^^^^^^^^^^^^^^^^^^^^
  File "C:\Users\JAIMIL KOTHARI\AppData\Roaming\Python\Python313\site-packages\mysql\connector\connection.py", line 1430, in _execute_query
    self.handle_unread_result()
    ~~~~~~~~~~~~~~~~~~~~~~~~~^^
  File "C:\Users\JAIMIL KOTHARI\AppData\Roaming\Python\Python313\site-packages\mysql\connector\connection.py", line 1740, in handle_unread_result
    raise InternalError("Unread result found")
mysql.connector.errors.InternalError: Unread result found

The above exception was the direct cause of the following exception:

Traceback (most recent call last):
  File "C:\Users\JAIMIL KOTHARI\AppData\Roaming\Python\Python313\site-packages\flask\app.py", line 1511, in wsgi_app
    response = self.full_dispatch_request()
  File "C:\Users\JAIMIL KOTHARI\AppData\Roaming\Python\Python313\site-packages\flask\app.py", line 919, in full_dispatch_request
    rv = self.handle_user_exception(e)
  File "C:\Users\JAIMIL KOTHARI\AppData\Roaming\Python\Python313\site-packages\flask_cors\extension.py", line 176, in wrapped_function
    return cors_after_request(app.make_response(f(*args, **kwargs)))
                                                ~^^^^^^^^^^^^^^^^^
  File "C:\Users\JAIMIL KOTHARI\AppData\Roaming\Python\Python313\site-packages\flask\app.py", line 917, in full_dispatch_request
    rv = self.dispatch_request()
  File "C:\Users\JAIMIL KOTHARI\AppData\Roaming\Python\Python313\site-packages\flask\app.py", line 902, in dispatch_request
    return self.ensure_sync(self.view_functions[rule.endpoint])(**view_args)  # type: ignore[no-any-return]
           ~~~~~~~~~~~~~~~~~~~~~~~~~~~~~~~~~~~~~~~~~~~~~~~~~~~~^^^^^^^^^^^^^
  File "C:\xampp\htdocs\Inbox\tripglide\backend\login.py", line 384, in flight_bookings
    db.reconnect()  # Attempt to reconnect if disconnected
    ~~~~~~~~~~~~^^
  File "C:\Users\JAIMIL KOTHARI\AppData\Roaming\Python\Python313\site-packages\mysql\connector\abstracts.py", line 1601, in reconnect
    raise InterfaceError(msg) from err
mysql.connector.errors.InterfaceError: Can not reconnect to MySQL after 1 attempt(s): Unread result found
2025-04-11 22:53:16,688 - ERROR - 500 GET /api/flight_bookings?user_id=44 (127.0.0.1) 38.61ms
2025-04-11 22:53:53,173 - INFO - C:\xampp\htdocs\Inbox\tripglide\backend\login.py modified; restarting server
2025-04-11 22:59:11,343 - DEBUG - Starting authorization phase
2025-04-11 22:59:11,345 - DEBUG - The provided initial strategy is mysql_native_password
2025-04-11 22:59:11,345 - INFO - package: mysql.connector.plugins
2025-04-11 22:59:11,345 - INFO - plugin_name: mysql_native_password
2025-04-11 22:59:11,348 - INFO - AUTHENTICATION_PLUGIN_CLASS: MySQLNativePasswordAuthPlugin
2025-04-11 22:59:11,351 - DEBUG - mysql_native_password completed succesfully
2025-04-11 22:59:11,361 - INFO - Database connection established
2025-04-11 22:59:11,375 - INFO - Database tables initialized
2025-04-11 22:59:11,377 - INFO - Twilio client initialized successfully
2025-04-11 22:59:11,382 - INFO - Serving on http://0.0.0.0:5001
2025-04-11 22:59:11,383 - DEBUG - Using selector: SelectSelector
2025-04-11 22:59:11,388 - INFO - Start watching changes
2025-04-11 22:59:11,389 - INFO - Start detecting changes
2025-04-11 22:59:16,463 - ERROR - Database error in profile: Unread result found
2025-04-11 22:59:16,466 - ERROR - 500 GET /api/profile?identifier=jaimilkothari2003@gmail.com (127.0.0.1) 21.15ms
2025-04-11 22:59:16,477 - DEBUG - Starting authorization phase
2025-04-11 22:59:16,478 - DEBUG - The provided initial strategy is mysql_native_password
2025-04-11 22:59:16,478 - DEBUG - mysql_native_password completed succesfully
2025-04-11 22:59:16,479 - ERROR - Exception on /api/flight_bookings [GET]
Traceback (most recent call last):
  File "C:\Users\JAIMIL KOTHARI\AppData\Roaming\Python\Python313\site-packages\mysql\connector\abstracts.py", line 1592, in reconnect
    self.connect()
    ~~~~~~~~~~~~^^
  File "C:\Users\JAIMIL KOTHARI\AppData\Roaming\Python\Python313\site-packages\mysql\connector\abstracts.py", line 1541, in connect
    self._post_connection()
    ~~~~~~~~~~~~~~~~~~~~~^^
  File "C:\Users\JAIMIL KOTHARI\AppData\Roaming\Python\Python313\site-packages\mysql\connector\abstracts.py", line 1481, in _post_connection
    self.set_charset_collation(charset=self._charset_id)
    ~~~~~~~~~~~~~~~~~~~~~~~~~~^^^^^^^^^^^^^^^^^^^^^^^^^^
  File "C:\Users\JAIMIL KOTHARI\AppData\Roaming\Python\Python313\site-packages\mysql\connector\abstracts.py", line 1366, in set_charset_collation
    self._execute_query(f"SET NAMES '{charset_name}' COLLATE '{collation_name}'")
    ~~~~~~~~~~~~~~~~~~~^^^^^^^^^^^^^^^^^^^^^^^^^^^^^^^^^^^^^^^^^^^^^^^^^^^^^^^^^^
  File "C:\Users\JAIMIL KOTHARI\AppData\Roaming\Python\Python313\site-packages\mysql\connector\connection.py", line 1430, in _execute_query
    self.handle_unread_result()
    ~~~~~~~~~~~~~~~~~~~~~~~~~^^
  File "C:\Users\JAIMIL KOTHARI\AppData\Roaming\Python\Python313\site-packages\mysql\connector\connection.py", line 1740, in handle_unread_result
    raise InternalError("Unread result found")
mysql.connector.errors.InternalError: Unread result found

The above exception was the direct cause of the following exception:

Traceback (most recent call last):
  File "C:\Users\JAIMIL KOTHARI\AppData\Roaming\Python\Python313\site-packages\flask\app.py", line 1511, in wsgi_app
    response = self.full_dispatch_request()
  File "C:\Users\JAIMIL KOTHARI\AppData\Roaming\Python\Python313\site-packages\flask\app.py", line 919, in full_dispatch_request
    rv = self.handle_user_exception(e)
  File "C:\Users\JAIMIL KOTHARI\AppData\Roaming\Python\Python313\site-packages\flask_cors\extension.py", line 176, in wrapped_function
    return cors_after_request(app.make_response(f(*args, **kwargs)))
                                                ~^^^^^^^^^^^^^^^^^
  File "C:\Users\JAIMIL KOTHARI\AppData\Roaming\Python\Python313\site-packages\flask\app.py", line 917, in full_dispatch_request
    rv = self.dispatch_request()
  File "C:\Users\JAIMIL KOTHARI\AppData\Roaming\Python\Python313\site-packages\flask\app.py", line 902, in dispatch_request
    return self.ensure_sync(self.view_functions[rule.endpoint])(**view_args)  # type: ignore[no-any-return]
           ~~~~~~~~~~~~~~~~~~~~~~~~~~~~~~~~~~~~~~~~~~~~~~~~~~~~^^^^^^^^^^^^^
  File "C:\xampp\htdocs\Inbox\tripglide\backend\login.py", line 615, in flight_bookings
    db.reconnect()
    ~~~~~~~~~~~~^^
  File "C:\Users\JAIMIL KOTHARI\AppData\Roaming\Python\Python313\site-packages\mysql\connector\abstracts.py", line 1601, in reconnect
    raise InterfaceError(msg) from err
mysql.connector.errors.InterfaceError: Can not reconnect to MySQL after 1 attempt(s): Unread result found
2025-04-11 22:59:16,516 - ERROR - 500 GET /api/flight_bookings?user_id=44 (127.0.0.1) 47.85ms
2025-04-11 22:59:16,523 - DEBUG - Starting authorization phase
2025-04-11 22:59:16,524 - DEBUG - The provided initial strategy is mysql_native_password
2025-04-11 22:59:16,527 - DEBUG - mysql_native_password completed succesfully
2025-04-11 22:59:16,527 - ERROR - Exception on /api/profile [GET]
Traceback (most recent call last):
  File "C:\Users\JAIMIL KOTHARI\AppData\Roaming\Python\Python313\site-packages\mysql\connector\abstracts.py", line 1592, in reconnect
    self.connect()
    ~~~~~~~~~~~~^^
  File "C:\Users\JAIMIL KOTHARI\AppData\Roaming\Python\Python313\site-packages\mysql\connector\abstracts.py", line 1541, in connect
    self._post_connection()
    ~~~~~~~~~~~~~~~~~~~~~^^
  File "C:\Users\JAIMIL KOTHARI\AppData\Roaming\Python\Python313\site-packages\mysql\connector\abstracts.py", line 1481, in _post_connection
    self.set_charset_collation(charset=self._charset_id)
    ~~~~~~~~~~~~~~~~~~~~~~~~~~^^^^^^^^^^^^^^^^^^^^^^^^^^
  File "C:\Users\JAIMIL KOTHARI\AppData\Roaming\Python\Python313\site-packages\mysql\connector\abstracts.py", line 1366, in set_charset_collation
    self._execute_query(f"SET NAMES '{charset_name}' COLLATE '{collation_name}'")
    ~~~~~~~~~~~~~~~~~~~^^^^^^^^^^^^^^^^^^^^^^^^^^^^^^^^^^^^^^^^^^^^^^^^^^^^^^^^^^
  File "C:\Users\JAIMIL KOTHARI\AppData\Roaming\Python\Python313\site-packages\mysql\connector\connection.py", line 1430, in _execute_query
    self.handle_unread_result()
    ~~~~~~~~~~~~~~~~~~~~~~~~~^^
  File "C:\Users\JAIMIL KOTHARI\AppData\Roaming\Python\Python313\site-packages\mysql\connector\connection.py", line 1740, in handle_unread_result
    raise InternalError("Unread result found")
mysql.connector.errors.InternalError: Unread result found

The above exception was the direct cause of the following exception:

Traceback (most recent call last):
  File "C:\Users\JAIMIL KOTHARI\AppData\Roaming\Python\Python313\site-packages\flask\app.py", line 1511, in wsgi_app
    response = self.full_dispatch_request()
  File "C:\Users\JAIMIL KOTHARI\AppData\Roaming\Python\Python313\site-packages\flask\app.py", line 919, in full_dispatch_request
    rv = self.handle_user_exception(e)
  File "C:\Users\JAIMIL KOTHARI\AppData\Roaming\Python\Python313\site-packages\flask_cors\extension.py", line 176, in wrapped_function
    return cors_after_request(app.make_response(f(*args, **kwargs)))
                                                ~^^^^^^^^^^^^^^^^^
  File "C:\Users\JAIMIL KOTHARI\AppData\Roaming\Python\Python313\site-packages\flask\app.py", line 917, in full_dispatch_request
    rv = self.dispatch_request()
  File "C:\Users\JAIMIL KOTHARI\AppData\Roaming\Python\Python313\site-packages\flask\app.py", line 902, in dispatch_request
    return self.ensure_sync(self.view_functions[rule.endpoint])(**view_args)  # type: ignore[no-any-return]
           ~~~~~~~~~~~~~~~~~~~~~~~~~~~~~~~~~~~~~~~~~~~~~~~~~~~~^^^^^^^^^^^^^
  File "C:\xampp\htdocs\Inbox\tripglide\backend\login.py", line 464, in profile
    db.reconnect()
    ~~~~~~~~~~~~^^
  File "C:\Users\JAIMIL KOTHARI\AppData\Roaming\Python\Python313\site-packages\mysql\connector\abstracts.py", line 1601, in reconnect
    raise InterfaceError(msg) from err
mysql.connector.errors.InterfaceError: Can not reconnect to MySQL after 1 attempt(s): Unread result found
2025-04-11 22:59:16,533 - ERROR - 500 GET /api/profile?identifier=jaimilkothari2003@gmail.com (127.0.0.1) 15.87ms
2025-04-11 22:59:16,542 - DEBUG - Starting authorization phase
2025-04-11 22:59:16,542 - DEBUG - The provided initial strategy is mysql_native_password
2025-04-11 22:59:16,543 - DEBUG - mysql_native_password completed succesfully
2025-04-11 22:59:16,543 - ERROR - Exception on /api/flight_bookings [GET]
Traceback (most recent call last):
  File "C:\Users\JAIMIL KOTHARI\AppData\Roaming\Python\Python313\site-packages\mysql\connector\abstracts.py", line 1592, in reconnect
    self.connect()
    ~~~~~~~~~~~~^^
  File "C:\Users\JAIMIL KOTHARI\AppData\Roaming\Python\Python313\site-packages\mysql\connector\abstracts.py", line 1541, in connect
    self._post_connection()
    ~~~~~~~~~~~~~~~~~~~~~^^
  File "C:\Users\JAIMIL KOTHARI\AppData\Roaming\Python\Python313\site-packages\mysql\connector\abstracts.py", line 1481, in _post_connection
    self.set_charset_collation(charset=self._charset_id)
    ~~~~~~~~~~~~~~~~~~~~~~~~~~^^^^^^^^^^^^^^^^^^^^^^^^^^
  File "C:\Users\JAIMIL KOTHARI\AppData\Roaming\Python\Python313\site-packages\mysql\connector\abstracts.py", line 1366, in set_charset_collation
    self._execute_query(f"SET NAMES '{charset_name}' COLLATE '{collation_name}'")
    ~~~~~~~~~~~~~~~~~~~^^^^^^^^^^^^^^^^^^^^^^^^^^^^^^^^^^^^^^^^^^^^^^^^^^^^^^^^^^
  File "C:\Users\JAIMIL KOTHARI\AppData\Roaming\Python\Python313\site-packages\mysql\connector\connection.py", line 1430, in _execute_query
    self.handle_unread_result()
    ~~~~~~~~~~~~~~~~~~~~~~~~~^^
  File "C:\Users\JAIMIL KOTHARI\AppData\Roaming\Python\Python313\site-packages\mysql\connector\connection.py", line 1740, in handle_unread_result
    raise InternalError("Unread result found")
mysql.connector.errors.InternalError: Unread result found

The above exception was the direct cause of the following exception:

Traceback (most recent call last):
  File "C:\Users\JAIMIL KOTHARI\AppData\Roaming\Python\Python313\site-packages\flask\app.py", line 1511, in wsgi_app
    response = self.full_dispatch_request()
  File "C:\Users\JAIMIL KOTHARI\AppData\Roaming\Python\Python313\site-packages\flask\app.py", line 919, in full_dispatch_request
    rv = self.handle_user_exception(e)
  File "C:\Users\JAIMIL KOTHARI\AppData\Roaming\Python\Python313\site-packages\flask_cors\extension.py", line 176, in wrapped_function
    return cors_after_request(app.make_response(f(*args, **kwargs)))
                                                ~^^^^^^^^^^^^^^^^^
  File "C:\Users\JAIMIL KOTHARI\AppData\Roaming\Python\Python313\site-packages\flask\app.py", line 917, in full_dispatch_request
    rv = self.dispatch_request()
  File "C:\Users\JAIMIL KOTHARI\AppData\Roaming\Python\Python313\site-packages\flask\app.py", line 902, in dispatch_request
    return self.ensure_sync(self.view_functions[rule.endpoint])(**view_args)  # type: ignore[no-any-return]
           ~~~~~~~~~~~~~~~~~~~~~~~~~~~~~~~~~~~~~~~~~~~~~~~~~~~~^^^^^^^^^^^^^
  File "C:\xampp\htdocs\Inbox\tripglide\backend\login.py", line 615, in flight_bookings
    db.reconnect()
    ~~~~~~~~~~~~^^
  File "C:\Users\JAIMIL KOTHARI\AppData\Roaming\Python\Python313\site-packages\mysql\connector\abstracts.py", line 1601, in reconnect
    raise InterfaceError(msg) from err
mysql.connector.errors.InterfaceError: Can not reconnect to MySQL after 1 attempt(s): Unread result found
2025-04-11 22:59:16,549 - ERROR - 500 GET /api/flight_bookings?user_id=44 (127.0.0.1) 11.62ms
2025-04-11 23:04:29,908 - DEBUG - Starting authorization phase
2025-04-11 23:04:29,908 - DEBUG - The provided initial strategy is mysql_native_password
2025-04-11 23:04:29,909 - DEBUG - mysql_native_password completed succesfully
2025-04-11 23:04:29,910 - ERROR - Exception on /api/profile [GET]
Traceback (most recent call last):
  File "C:\Users\JAIMIL KOTHARI\AppData\Roaming\Python\Python313\site-packages\mysql\connector\abstracts.py", line 1592, in reconnect
    self.connect()
    ~~~~~~~~~~~~^^
  File "C:\Users\JAIMIL KOTHARI\AppData\Roaming\Python\Python313\site-packages\mysql\connector\abstracts.py", line 1541, in connect
    self._post_connection()
    ~~~~~~~~~~~~~~~~~~~~~^^
  File "C:\Users\JAIMIL KOTHARI\AppData\Roaming\Python\Python313\site-packages\mysql\connector\abstracts.py", line 1481, in _post_connection
    self.set_charset_collation(charset=self._charset_id)
    ~~~~~~~~~~~~~~~~~~~~~~~~~~^^^^^^^^^^^^^^^^^^^^^^^^^^
  File "C:\Users\JAIMIL KOTHARI\AppData\Roaming\Python\Python313\site-packages\mysql\connector\abstracts.py", line 1366, in set_charset_collation
    self._execute_query(f"SET NAMES '{charset_name}' COLLATE '{collation_name}'")
    ~~~~~~~~~~~~~~~~~~~^^^^^^^^^^^^^^^^^^^^^^^^^^^^^^^^^^^^^^^^^^^^^^^^^^^^^^^^^^
  File "C:\Users\JAIMIL KOTHARI\AppData\Roaming\Python\Python313\site-packages\mysql\connector\connection.py", line 1430, in _execute_query
    self.handle_unread_result()
    ~~~~~~~~~~~~~~~~~~~~~~~~~^^
  File "C:\Users\JAIMIL KOTHARI\AppData\Roaming\Python\Python313\site-packages\mysql\connector\connection.py", line 1740, in handle_unread_result
    raise InternalError("Unread result found")
mysql.connector.errors.InternalError: Unread result found

The above exception was the direct cause of the following exception:

Traceback (most recent call last):
  File "C:\Users\JAIMIL KOTHARI\AppData\Roaming\Python\Python313\site-packages\flask\app.py", line 1511, in wsgi_app
    response = self.full_dispatch_request()
  File "C:\Users\JAIMIL KOTHARI\AppData\Roaming\Python\Python313\site-packages\flask\app.py", line 919, in full_dispatch_request
    rv = self.handle_user_exception(e)
  File "C:\Users\JAIMIL KOTHARI\AppData\Roaming\Python\Python313\site-packages\flask_cors\extension.py", line 176, in wrapped_function
    return cors_after_request(app.make_response(f(*args, **kwargs)))
                                                ~^^^^^^^^^^^^^^^^^
  File "C:\Users\JAIMIL KOTHARI\AppData\Roaming\Python\Python313\site-packages\flask\app.py", line 917, in full_dispatch_request
    rv = self.dispatch_request()
  File "C:\Users\JAIMIL KOTHARI\AppData\Roaming\Python\Python313\site-packages\flask\app.py", line 902, in dispatch_request
    return self.ensure_sync(self.view_functions[rule.endpoint])(**view_args)  # type: ignore[no-any-return]
           ~~~~~~~~~~~~~~~~~~~~~~~~~~~~~~~~~~~~~~~~~~~~~~~~~~~~^^^^^^^^^^^^^
  File "C:\xampp\htdocs\Inbox\tripglide\backend\login.py", line 464, in profile
    db.reconnect()
    ~~~~~~~~~~~~^^
  File "C:\Users\JAIMIL KOTHARI\AppData\Roaming\Python\Python313\site-packages\mysql\connector\abstracts.py", line 1601, in reconnect
    raise InterfaceError(msg) from err
mysql.connector.errors.InterfaceError: Can not reconnect to MySQL after 1 attempt(s): Unread result found
2025-04-11 23:04:29,918 - ERROR - 500 GET /api/profile?identifier=jaimilkothari2003%40gmail.com (127.0.0.1) 27.43ms
2025-04-11 23:04:29,925 - DEBUG - Starting authorization phase
2025-04-11 23:04:29,925 - DEBUG - The provided initial strategy is mysql_native_password
2025-04-11 23:04:29,925 - DEBUG - mysql_native_password completed succesfully
2025-04-11 23:04:29,926 - ERROR - Exception on /api/flight_bookings [GET]
Traceback (most recent call last):
  File "C:\Users\JAIMIL KOTHARI\AppData\Roaming\Python\Python313\site-packages\mysql\connector\abstracts.py", line 1592, in reconnect
    self.connect()
    ~~~~~~~~~~~~^^
  File "C:\Users\JAIMIL KOTHARI\AppData\Roaming\Python\Python313\site-packages\mysql\connector\abstracts.py", line 1541, in connect
    self._post_connection()
    ~~~~~~~~~~~~~~~~~~~~~^^
  File "C:\Users\JAIMIL KOTHARI\AppData\Roaming\Python\Python313\site-packages\mysql\connector\abstracts.py", line 1481, in _post_connection
    self.set_charset_collation(charset=self._charset_id)
    ~~~~~~~~~~~~~~~~~~~~~~~~~~^^^^^^^^^^^^^^^^^^^^^^^^^^
  File "C:\Users\JAIMIL KOTHARI\AppData\Roaming\Python\Python313\site-packages\mysql\connector\abstracts.py", line 1366, in set_charset_collation
    self._execute_query(f"SET NAMES '{charset_name}' COLLATE '{collation_name}'")
    ~~~~~~~~~~~~~~~~~~~^^^^^^^^^^^^^^^^^^^^^^^^^^^^^^^^^^^^^^^^^^^^^^^^^^^^^^^^^^
  File "C:\Users\JAIMIL KOTHARI\AppData\Roaming\Python\Python313\site-packages\mysql\connector\connection.py", line 1430, in _execute_query
    self.handle_unread_result()
    ~~~~~~~~~~~~~~~~~~~~~~~~~^^
  File "C:\Users\JAIMIL KOTHARI\AppData\Roaming\Python\Python313\site-packages\mysql\connector\connection.py", line 1740, in handle_unread_result
    raise InternalError("Unread result found")
mysql.connector.errors.InternalError: Unread result found

The above exception was the direct cause of the following exception:

Traceback (most recent call last):
  File "C:\Users\JAIMIL KOTHARI\AppData\Roaming\Python\Python313\site-packages\flask\app.py", line 1511, in wsgi_app
    response = self.full_dispatch_request()
  File "C:\Users\JAIMIL KOTHARI\AppData\Roaming\Python\Python313\site-packages\flask\app.py", line 919, in full_dispatch_request
    rv = self.handle_user_exception(e)
  File "C:\Users\JAIMIL KOTHARI\AppData\Roaming\Python\Python313\site-packages\flask_cors\extension.py", line 176, in wrapped_function
    return cors_after_request(app.make_response(f(*args, **kwargs)))
                                                ~^^^^^^^^^^^^^^^^^
  File "C:\Users\JAIMIL KOTHARI\AppData\Roaming\Python\Python313\site-packages\flask\app.py", line 917, in full_dispatch_request
    rv = self.dispatch_request()
  File "C:\Users\JAIMIL KOTHARI\AppData\Roaming\Python\Python313\site-packages\flask\app.py", line 902, in dispatch_request
    return self.ensure_sync(self.view_functions[rule.endpoint])(**view_args)  # type: ignore[no-any-return]
           ~~~~~~~~~~~~~~~~~~~~~~~~~~~~~~~~~~~~~~~~~~~~~~~~~~~~^^^^^^^^^^^^^
  File "C:\xampp\htdocs\Inbox\tripglide\backend\login.py", line 615, in flight_bookings
    db.reconnect()
    ~~~~~~~~~~~~^^
  File "C:\Users\JAIMIL KOTHARI\AppData\Roaming\Python\Python313\site-packages\mysql\connector\abstracts.py", line 1601, in reconnect
    raise InterfaceError(msg) from err
mysql.connector.errors.InterfaceError: Can not reconnect to MySQL after 1 attempt(s): Unread result found
2025-04-11 23:04:29,929 - ERROR - 500 GET /api/flight_bookings?user_id=44 (127.0.0.1) 32.95ms
2025-04-11 23:04:33,246 - DEBUG - Starting authorization phase
2025-04-11 23:04:33,246 - DEBUG - The provided initial strategy is mysql_native_password
2025-04-11 23:04:33,247 - DEBUG - mysql_native_password completed succesfully
2025-04-11 23:04:33,247 - ERROR - Exception on /api/profile [GET]
Traceback (most recent call last):
  File "C:\Users\JAIMIL KOTHARI\AppData\Roaming\Python\Python313\site-packages\mysql\connector\abstracts.py", line 1592, in reconnect
    self.connect()
    ~~~~~~~~~~~~^^
  File "C:\Users\JAIMIL KOTHARI\AppData\Roaming\Python\Python313\site-packages\mysql\connector\abstracts.py", line 1541, in connect
    self._post_connection()
    ~~~~~~~~~~~~~~~~~~~~~^^
  File "C:\Users\JAIMIL KOTHARI\AppData\Roaming\Python\Python313\site-packages\mysql\connector\abstracts.py", line 1481, in _post_connection
    self.set_charset_collation(charset=self._charset_id)
    ~~~~~~~~~~~~~~~~~~~~~~~~~~^^^^^^^^^^^^^^^^^^^^^^^^^^
  File "C:\Users\JAIMIL KOTHARI\AppData\Roaming\Python\Python313\site-packages\mysql\connector\abstracts.py", line 1366, in set_charset_collation
    self._execute_query(f"SET NAMES '{charset_name}' COLLATE '{collation_name}'")
    ~~~~~~~~~~~~~~~~~~~^^^^^^^^^^^^^^^^^^^^^^^^^^^^^^^^^^^^^^^^^^^^^^^^^^^^^^^^^^
  File "C:\Users\JAIMIL KOTHARI\AppData\Roaming\Python\Python313\site-packages\mysql\connector\connection.py", line 1430, in _execute_query
    self.handle_unread_result()
    ~~~~~~~~~~~~~~~~~~~~~~~~~^^
  File "C:\Users\JAIMIL KOTHARI\AppData\Roaming\Python\Python313\site-packages\mysql\connector\connection.py", line 1740, in handle_unread_result
    raise InternalError("Unread result found")
mysql.connector.errors.InternalError: Unread result found

The above exception was the direct cause of the following exception:

Traceback (most recent call last):
  File "C:\Users\JAIMIL KOTHARI\AppData\Roaming\Python\Python313\site-packages\flask\app.py", line 1511, in wsgi_app
    response = self.full_dispatch_request()
  File "C:\Users\JAIMIL KOTHARI\AppData\Roaming\Python\Python313\site-packages\flask\app.py", line 919, in full_dispatch_request
    rv = self.handle_user_exception(e)
  File "C:\Users\JAIMIL KOTHARI\AppData\Roaming\Python\Python313\site-packages\flask_cors\extension.py", line 176, in wrapped_function
    return cors_after_request(app.make_response(f(*args, **kwargs)))
                                                ~^^^^^^^^^^^^^^^^^
  File "C:\Users\JAIMIL KOTHARI\AppData\Roaming\Python\Python313\site-packages\flask\app.py", line 917, in full_dispatch_request
    rv = self.dispatch_request()
  File "C:\Users\JAIMIL KOTHARI\AppData\Roaming\Python\Python313\site-packages\flask\app.py", line 902, in dispatch_request
    return self.ensure_sync(self.view_functions[rule.endpoint])(**view_args)  # type: ignore[no-any-return]
           ~~~~~~~~~~~~~~~~~~~~~~~~~~~~~~~~~~~~~~~~~~~~~~~~~~~~^^^^^^^^^^^^^
  File "C:\xampp\htdocs\Inbox\tripglide\backend\login.py", line 464, in profile
    db.reconnect()
    ~~~~~~~~~~~~^^
  File "C:\Users\JAIMIL KOTHARI\AppData\Roaming\Python\Python313\site-packages\mysql\connector\abstracts.py", line 1601, in reconnect
    raise InterfaceError(msg) from err
mysql.connector.errors.InterfaceError: Can not reconnect to MySQL after 1 attempt(s): Unread result found
2025-04-11 23:04:33,251 - ERROR - 500 GET /api/profile?identifier=jaimilkothari2003%40gmail.com (127.0.0.1) 13.84ms
2025-04-11 23:04:33,254 - DEBUG - Starting authorization phase
2025-04-11 23:04:33,254 - DEBUG - The provided initial strategy is mysql_native_password
2025-04-11 23:04:33,255 - DEBUG - mysql_native_password completed succesfully
2025-04-11 23:04:33,255 - ERROR - Exception on /api/flight_bookings [GET]
Traceback (most recent call last):
  File "C:\Users\JAIMIL KOTHARI\AppData\Roaming\Python\Python313\site-packages\mysql\connector\abstracts.py", line 1592, in reconnect
    self.connect()
    ~~~~~~~~~~~~^^
  File "C:\Users\JAIMIL KOTHARI\AppData\Roaming\Python\Python313\site-packages\mysql\connector\abstracts.py", line 1541, in connect
    self._post_connection()
    ~~~~~~~~~~~~~~~~~~~~~^^
  File "C:\Users\JAIMIL KOTHARI\AppData\Roaming\Python\Python313\site-packages\mysql\connector\abstracts.py", line 1481, in _post_connection
    self.set_charset_collation(charset=self._charset_id)
    ~~~~~~~~~~~~~~~~~~~~~~~~~~^^^^^^^^^^^^^^^^^^^^^^^^^^
  File "C:\Users\JAIMIL KOTHARI\AppData\Roaming\Python\Python313\site-packages\mysql\connector\abstracts.py", line 1366, in set_charset_collation
    self._execute_query(f"SET NAMES '{charset_name}' COLLATE '{collation_name}'")
    ~~~~~~~~~~~~~~~~~~~^^^^^^^^^^^^^^^^^^^^^^^^^^^^^^^^^^^^^^^^^^^^^^^^^^^^^^^^^^
  File "C:\Users\JAIMIL KOTHARI\AppData\Roaming\Python\Python313\site-packages\mysql\connector\connection.py", line 1430, in _execute_query
    self.handle_unread_result()
    ~~~~~~~~~~~~~~~~~~~~~~~~~^^
  File "C:\Users\JAIMIL KOTHARI\AppData\Roaming\Python\Python313\site-packages\mysql\connector\connection.py", line 1740, in handle_unread_result
    raise InternalError("Unread result found")
mysql.connector.errors.InternalError: Unread result found

The above exception was the direct cause of the following exception:

Traceback (most recent call last):
  File "C:\Users\JAIMIL KOTHARI\AppData\Roaming\Python\Python313\site-packages\flask\app.py", line 1511, in wsgi_app
    response = self.full_dispatch_request()
  File "C:\Users\JAIMIL KOTHARI\AppData\Roaming\Python\Python313\site-packages\flask\app.py", line 919, in full_dispatch_request
    rv = self.handle_user_exception(e)
  File "C:\Users\JAIMIL KOTHARI\AppData\Roaming\Python\Python313\site-packages\flask_cors\extension.py", line 176, in wrapped_function
    return cors_after_request(app.make_response(f(*args, **kwargs)))
                                                ~^^^^^^^^^^^^^^^^^
  File "C:\Users\JAIMIL KOTHARI\AppData\Roaming\Python\Python313\site-packages\flask\app.py", line 917, in full_dispatch_request
    rv = self.dispatch_request()
  File "C:\Users\JAIMIL KOTHARI\AppData\Roaming\Python\Python313\site-packages\flask\app.py", line 902, in dispatch_request
    return self.ensure_sync(self.view_functions[rule.endpoint])(**view_args)  # type: ignore[no-any-return]
           ~~~~~~~~~~~~~~~~~~~~~~~~~~~~~~~~~~~~~~~~~~~~~~~~~~~~^^^^^^^^^^^^^
  File "C:\xampp\htdocs\Inbox\tripglide\backend\login.py", line 615, in flight_bookings
    db.reconnect()
    ~~~~~~~~~~~~^^
  File "C:\Users\JAIMIL KOTHARI\AppData\Roaming\Python\Python313\site-packages\mysql\connector\abstracts.py", line 1601, in reconnect
    raise InterfaceError(msg) from err
mysql.connector.errors.InterfaceError: Can not reconnect to MySQL after 1 attempt(s): Unread result found
2025-04-11 23:04:33,260 - ERROR - 500 GET /api/flight_bookings?user_id=44 (127.0.0.1) 7.82ms
2025-04-11 23:04:33,263 - DEBUG - Starting authorization phase
2025-04-11 23:04:33,263 - DEBUG - The provided initial strategy is mysql_native_password
2025-04-11 23:04:33,264 - DEBUG - mysql_native_password completed succesfully
2025-04-11 23:04:33,265 - ERROR - Exception on /api/profile [GET]
Traceback (most recent call last):
  File "C:\Users\JAIMIL KOTHARI\AppData\Roaming\Python\Python313\site-packages\mysql\connector\abstracts.py", line 1592, in reconnect
    self.connect()
    ~~~~~~~~~~~~^^
  File "C:\Users\JAIMIL KOTHARI\AppData\Roaming\Python\Python313\site-packages\mysql\connector\abstracts.py", line 1541, in connect
    self._post_connection()
    ~~~~~~~~~~~~~~~~~~~~~^^
  File "C:\Users\JAIMIL KOTHARI\AppData\Roaming\Python\Python313\site-packages\mysql\connector\abstracts.py", line 1481, in _post_connection
    self.set_charset_collation(charset=self._charset_id)
    ~~~~~~~~~~~~~~~~~~~~~~~~~~^^^^^^^^^^^^^^^^^^^^^^^^^^
  File "C:\Users\JAIMIL KOTHARI\AppData\Roaming\Python\Python313\site-packages\mysql\connector\abstracts.py", line 1366, in set_charset_collation
    self._execute_query(f"SET NAMES '{charset_name}' COLLATE '{collation_name}'")
    ~~~~~~~~~~~~~~~~~~~^^^^^^^^^^^^^^^^^^^^^^^^^^^^^^^^^^^^^^^^^^^^^^^^^^^^^^^^^^
  File "C:\Users\JAIMIL KOTHARI\AppData\Roaming\Python\Python313\site-packages\mysql\connector\connection.py", line 1430, in _execute_query
    self.handle_unread_result()
    ~~~~~~~~~~~~~~~~~~~~~~~~~^^
  File "C:\Users\JAIMIL KOTHARI\AppData\Roaming\Python\Python313\site-packages\mysql\connector\connection.py", line 1740, in handle_unread_result
    raise InternalError("Unread result found")
mysql.connector.errors.InternalError: Unread result found

The above exception was the direct cause of the following exception:

Traceback (most recent call last):
  File "C:\Users\JAIMIL KOTHARI\AppData\Roaming\Python\Python313\site-packages\flask\app.py", line 1511, in wsgi_app
    response = self.full_dispatch_request()
  File "C:\Users\JAIMIL KOTHARI\AppData\Roaming\Python\Python313\site-packages\flask\app.py", line 919, in full_dispatch_request
    rv = self.handle_user_exception(e)
  File "C:\Users\JAIMIL KOTHARI\AppData\Roaming\Python\Python313\site-packages\flask_cors\extension.py", line 176, in wrapped_function
    return cors_after_request(app.make_response(f(*args, **kwargs)))
                                                ~^^^^^^^^^^^^^^^^^
  File "C:\Users\JAIMIL KOTHARI\AppData\Roaming\Python\Python313\site-packages\flask\app.py", line 917, in full_dispatch_request
    rv = self.dispatch_request()
  File "C:\Users\JAIMIL KOTHARI\AppData\Roaming\Python\Python313\site-packages\flask\app.py", line 902, in dispatch_request
    return self.ensure_sync(self.view_functions[rule.endpoint])(**view_args)  # type: ignore[no-any-return]
           ~~~~~~~~~~~~~~~~~~~~~~~~~~~~~~~~~~~~~~~~~~~~~~~~~~~~^^^^^^^^^^^^^
  File "C:\xampp\htdocs\Inbox\tripglide\backend\login.py", line 464, in profile
    db.reconnect()
    ~~~~~~~~~~~~^^
  File "C:\Users\JAIMIL KOTHARI\AppData\Roaming\Python\Python313\site-packages\mysql\connector\abstracts.py", line 1601, in reconnect
    raise InterfaceError(msg) from err
mysql.connector.errors.InterfaceError: Can not reconnect to MySQL after 1 attempt(s): Unread result found
2025-04-11 23:04:33,269 - ERROR - 500 GET /api/profile?identifier=jaimilkothari2003%40gmail.com (127.0.0.1) 8.47ms
2025-04-11 23:04:33,275 - DEBUG - Starting authorization phase
2025-04-11 23:04:33,275 - DEBUG - The provided initial strategy is mysql_native_password
2025-04-11 23:04:33,276 - DEBUG - mysql_native_password completed succesfully
2025-04-11 23:04:33,276 - ERROR - Exception on /api/flight_bookings [GET]
Traceback (most recent call last):
  File "C:\Users\JAIMIL KOTHARI\AppData\Roaming\Python\Python313\site-packages\mysql\connector\abstracts.py", line 1592, in reconnect
    self.connect()
    ~~~~~~~~~~~~^^
  File "C:\Users\JAIMIL KOTHARI\AppData\Roaming\Python\Python313\site-packages\mysql\connector\abstracts.py", line 1541, in connect
    self._post_connection()
    ~~~~~~~~~~~~~~~~~~~~~^^
  File "C:\Users\JAIMIL KOTHARI\AppData\Roaming\Python\Python313\site-packages\mysql\connector\abstracts.py", line 1481, in _post_connection
    self.set_charset_collation(charset=self._charset_id)
    ~~~~~~~~~~~~~~~~~~~~~~~~~~^^^^^^^^^^^^^^^^^^^^^^^^^^
  File "C:\Users\JAIMIL KOTHARI\AppData\Roaming\Python\Python313\site-packages\mysql\connector\abstracts.py", line 1366, in set_charset_collation
    self._execute_query(f"SET NAMES '{charset_name}' COLLATE '{collation_name}'")
    ~~~~~~~~~~~~~~~~~~~^^^^^^^^^^^^^^^^^^^^^^^^^^^^^^^^^^^^^^^^^^^^^^^^^^^^^^^^^^
  File "C:\Users\JAIMIL KOTHARI\AppData\Roaming\Python\Python313\site-packages\mysql\connector\connection.py", line 1430, in _execute_query
    self.handle_unread_result()
    ~~~~~~~~~~~~~~~~~~~~~~~~~^^
  File "C:\Users\JAIMIL KOTHARI\AppData\Roaming\Python\Python313\site-packages\mysql\connector\connection.py", line 1740, in handle_unread_result
    raise InternalError("Unread result found")
mysql.connector.errors.InternalError: Unread result found

The above exception was the direct cause of the following exception:

Traceback (most recent call last):
  File "C:\Users\JAIMIL KOTHARI\AppData\Roaming\Python\Python313\site-packages\flask\app.py", line 1511, in wsgi_app
    response = self.full_dispatch_request()
  File "C:\Users\JAIMIL KOTHARI\AppData\Roaming\Python\Python313\site-packages\flask\app.py", line 919, in full_dispatch_request
    rv = self.handle_user_exception(e)
  File "C:\Users\JAIMIL KOTHARI\AppData\Roaming\Python\Python313\site-packages\flask_cors\extension.py", line 176, in wrapped_function
    return cors_after_request(app.make_response(f(*args, **kwargs)))
                                                ~^^^^^^^^^^^^^^^^^
  File "C:\Users\JAIMIL KOTHARI\AppData\Roaming\Python\Python313\site-packages\flask\app.py", line 917, in full_dispatch_request
    rv = self.dispatch_request()
  File "C:\Users\JAIMIL KOTHARI\AppData\Roaming\Python\Python313\site-packages\flask\app.py", line 902, in dispatch_request
    return self.ensure_sync(self.view_functions[rule.endpoint])(**view_args)  # type: ignore[no-any-return]
           ~~~~~~~~~~~~~~~~~~~~~~~~~~~~~~~~~~~~~~~~~~~~~~~~~~~~^^^^^^^^^^^^^
  File "C:\xampp\htdocs\Inbox\tripglide\backend\login.py", line 615, in flight_bookings
    db.reconnect()
    ~~~~~~~~~~~~^^
  File "C:\Users\JAIMIL KOTHARI\AppData\Roaming\Python\Python313\site-packages\mysql\connector\abstracts.py", line 1601, in reconnect
    raise InterfaceError(msg) from err
mysql.connector.errors.InterfaceError: Can not reconnect to MySQL after 1 attempt(s): Unread result found
2025-04-11 23:04:33,281 - ERROR - 500 GET /api/flight_bookings?user_id=44 (127.0.0.1) 9.53ms
2025-04-11 23:05:30,850 - DEBUG - Starting authorization phase
2025-04-11 23:05:30,851 - DEBUG - The provided initial strategy is mysql_native_password
2025-04-11 23:05:30,851 - DEBUG - mysql_native_password completed succesfully
2025-04-11 23:05:30,852 - ERROR - Exception on /api/flight_bookings [GET]
Traceback (most recent call last):
  File "C:\Users\JAIMIL KOTHARI\AppData\Roaming\Python\Python313\site-packages\mysql\connector\abstracts.py", line 1592, in reconnect
    self.connect()
    ~~~~~~~~~~~~^^
  File "C:\Users\JAIMIL KOTHARI\AppData\Roaming\Python\Python313\site-packages\mysql\connector\abstracts.py", line 1541, in connect
    self._post_connection()
    ~~~~~~~~~~~~~~~~~~~~~^^
  File "C:\Users\JAIMIL KOTHARI\AppData\Roaming\Python\Python313\site-packages\mysql\connector\abstracts.py", line 1481, in _post_connection
    self.set_charset_collation(charset=self._charset_id)
    ~~~~~~~~~~~~~~~~~~~~~~~~~~^^^^^^^^^^^^^^^^^^^^^^^^^^
  File "C:\Users\JAIMIL KOTHARI\AppData\Roaming\Python\Python313\site-packages\mysql\connector\abstracts.py", line 1366, in set_charset_collation
    self._execute_query(f"SET NAMES '{charset_name}' COLLATE '{collation_name}'")
    ~~~~~~~~~~~~~~~~~~~^^^^^^^^^^^^^^^^^^^^^^^^^^^^^^^^^^^^^^^^^^^^^^^^^^^^^^^^^^
  File "C:\Users\JAIMIL KOTHARI\AppData\Roaming\Python\Python313\site-packages\mysql\connector\connection.py", line 1430, in _execute_query
    self.handle_unread_result()
    ~~~~~~~~~~~~~~~~~~~~~~~~~^^
  File "C:\Users\JAIMIL KOTHARI\AppData\Roaming\Python\Python313\site-packages\mysql\connector\connection.py", line 1740, in handle_unread_result
    raise InternalError("Unread result found")
mysql.connector.errors.InternalError: Unread result found

The above exception was the direct cause of the following exception:

Traceback (most recent call last):
  File "C:\Users\JAIMIL KOTHARI\AppData\Roaming\Python\Python313\site-packages\flask\app.py", line 1511, in wsgi_app
    response = self.full_dispatch_request()
  File "C:\Users\JAIMIL KOTHARI\AppData\Roaming\Python\Python313\site-packages\flask\app.py", line 919, in full_dispatch_request
    rv = self.handle_user_exception(e)
  File "C:\Users\JAIMIL KOTHARI\AppData\Roaming\Python\Python313\site-packages\flask_cors\extension.py", line 176, in wrapped_function
    return cors_after_request(app.make_response(f(*args, **kwargs)))
                                                ~^^^^^^^^^^^^^^^^^
  File "C:\Users\JAIMIL KOTHARI\AppData\Roaming\Python\Python313\site-packages\flask\app.py", line 917, in full_dispatch_request
    rv = self.dispatch_request()
  File "C:\Users\JAIMIL KOTHARI\AppData\Roaming\Python\Python313\site-packages\flask\app.py", line 902, in dispatch_request
    return self.ensure_sync(self.view_functions[rule.endpoint])(**view_args)  # type: ignore[no-any-return]
           ~~~~~~~~~~~~~~~~~~~~~~~~~~~~~~~~~~~~~~~~~~~~~~~~~~~~^^^^^^^^^^^^^
  File "C:\xampp\htdocs\Inbox\tripglide\backend\login.py", line 615, in flight_bookings
    db.reconnect()
    ~~~~~~~~~~~~^^
  File "C:\Users\JAIMIL KOTHARI\AppData\Roaming\Python\Python313\site-packages\mysql\connector\abstracts.py", line 1601, in reconnect
    raise InterfaceError(msg) from err
mysql.connector.errors.InterfaceError: Can not reconnect to MySQL after 1 attempt(s): Unread result found
2025-04-11 23:05:30,858 - ERROR - 500 GET /api/flight_bookings?user_id=44 (127.0.0.1) 9.23ms
2025-04-11 23:05:30,861 - DEBUG - Starting authorization phase
2025-04-11 23:05:30,861 - DEBUG - The provided initial strategy is mysql_native_password
2025-04-11 23:05:30,861 - DEBUG - mysql_native_password completed succesfully
2025-04-11 23:05:30,862 - ERROR - Exception on /api/profile [GET]
Traceback (most recent call last):
  File "C:\Users\JAIMIL KOTHARI\AppData\Roaming\Python\Python313\site-packages\mysql\connector\abstracts.py", line 1592, in reconnect
    self.connect()
    ~~~~~~~~~~~~^^
  File "C:\Users\JAIMIL KOTHARI\AppData\Roaming\Python\Python313\site-packages\mysql\connector\abstracts.py", line 1541, in connect
    self._post_connection()
    ~~~~~~~~~~~~~~~~~~~~~^^
  File "C:\Users\JAIMIL KOTHARI\AppData\Roaming\Python\Python313\site-packages\mysql\connector\abstracts.py", line 1481, in _post_connection
    self.set_charset_collation(charset=self._charset_id)
    ~~~~~~~~~~~~~~~~~~~~~~~~~~^^^^^^^^^^^^^^^^^^^^^^^^^^
  File "C:\Users\JAIMIL KOTHARI\AppData\Roaming\Python\Python313\site-packages\mysql\connector\abstracts.py", line 1366, in set_charset_collation
    self._execute_query(f"SET NAMES '{charset_name}' COLLATE '{collation_name}'")
    ~~~~~~~~~~~~~~~~~~~^^^^^^^^^^^^^^^^^^^^^^^^^^^^^^^^^^^^^^^^^^^^^^^^^^^^^^^^^^
  File "C:\Users\JAIMIL KOTHARI\AppData\Roaming\Python\Python313\site-packages\mysql\connector\connection.py", line 1430, in _execute_query
    self.handle_unread_result()
    ~~~~~~~~~~~~~~~~~~~~~~~~~^^
  File "C:\Users\JAIMIL KOTHARI\AppData\Roaming\Python\Python313\site-packages\mysql\connector\connection.py", line 1740, in handle_unread_result
    raise InternalError("Unread result found")
mysql.connector.errors.InternalError: Unread result found

The above exception was the direct cause of the following exception:

Traceback (most recent call last):
  File "C:\Users\JAIMIL KOTHARI\AppData\Roaming\Python\Python313\site-packages\flask\app.py", line 1511, in wsgi_app
    response = self.full_dispatch_request()
  File "C:\Users\JAIMIL KOTHARI\AppData\Roaming\Python\Python313\site-packages\flask\app.py", line 919, in full_dispatch_request
    rv = self.handle_user_exception(e)
  File "C:\Users\JAIMIL KOTHARI\AppData\Roaming\Python\Python313\site-packages\flask_cors\extension.py", line 176, in wrapped_function
    return cors_after_request(app.make_response(f(*args, **kwargs)))
                                                ~^^^^^^^^^^^^^^^^^
  File "C:\Users\JAIMIL KOTHARI\AppData\Roaming\Python\Python313\site-packages\flask\app.py", line 917, in full_dispatch_request
    rv = self.dispatch_request()
  File "C:\Users\JAIMIL KOTHARI\AppData\Roaming\Python\Python313\site-packages\flask\app.py", line 902, in dispatch_request
    return self.ensure_sync(self.view_functions[rule.endpoint])(**view_args)  # type: ignore[no-any-return]
           ~~~~~~~~~~~~~~~~~~~~~~~~~~~~~~~~~~~~~~~~~~~~~~~~~~~~^^^^^^^^^^^^^
  File "C:\xampp\htdocs\Inbox\tripglide\backend\login.py", line 464, in profile
    db.reconnect()
    ~~~~~~~~~~~~^^
  File "C:\Users\JAIMIL KOTHARI\AppData\Roaming\Python\Python313\site-packages\mysql\connector\abstracts.py", line 1601, in reconnect
    raise InterfaceError(msg) from err
mysql.connector.errors.InterfaceError: Can not reconnect to MySQL after 1 attempt(s): Unread result found
2025-04-11 23:05:30,866 - ERROR - 500 GET /api/profile?identifier=jaimilkothari2003@gmail.com (127.0.0.1) 7.21ms
2025-04-11 23:05:38,891 - INFO - C:\xampp\htdocs\Inbox\tripglide\backend\login.py modified; restarting server
2025-04-11 23:09:14,600 - DEBUG - Starting authorization phase
2025-04-11 23:09:14,601 - DEBUG - The provided initial strategy is mysql_native_password
2025-04-11 23:09:14,601 - INFO - package: mysql.connector.plugins
2025-04-11 23:09:14,601 - INFO - plugin_name: mysql_native_password
2025-04-11 23:09:14,604 - INFO - AUTHENTICATION_PLUGIN_CLASS: MySQLNativePasswordAuthPlugin
2025-04-11 23:09:14,606 - DEBUG - mysql_native_password completed succesfully
2025-04-11 23:09:14,611 - INFO - Database connection established
2025-04-11 23:09:14,622 - INFO - Database tables initialized
2025-04-11 23:09:14,625 - INFO - Twilio client initialized successfully
2025-04-11 23:09:14,637 - INFO - Serving on http://0.0.0.0:5001
2025-04-11 23:09:14,639 - DEBUG - Using selector: SelectSelector
2025-04-11 23:09:14,644 - INFO - Start watching changes
2025-04-11 23:09:14,644 - INFO - Start detecting changes
2025-04-11 23:09:14,904 - ERROR - Database error in profile: Unread result found
2025-04-11 23:09:14,906 - ERROR - 500 GET /api/profile?identifier=jaimilkothari2003%40gmail.com (127.0.0.1) 5.97ms
2025-04-11 23:09:14,911 - DEBUG - Starting authorization phase
2025-04-11 23:09:14,912 - DEBUG - The provided initial strategy is mysql_native_password
2025-04-11 23:09:14,912 - DEBUG - mysql_native_password completed succesfully
2025-04-11 23:09:14,913 - ERROR - Exception on /api/flight_bookings [GET]
Traceback (most recent call last):
  File "C:\Users\JAIMIL KOTHARI\AppData\Roaming\Python\Python313\site-packages\mysql\connector\abstracts.py", line 1592, in reconnect
    self.connect()
    ~~~~~~~~~~~~^^
  File "C:\Users\JAIMIL KOTHARI\AppData\Roaming\Python\Python313\site-packages\mysql\connector\abstracts.py", line 1541, in connect
    self._post_connection()
    ~~~~~~~~~~~~~~~~~~~~~^^
  File "C:\Users\JAIMIL KOTHARI\AppData\Roaming\Python\Python313\site-packages\mysql\connector\abstracts.py", line 1481, in _post_connection
    self.set_charset_collation(charset=self._charset_id)
    ~~~~~~~~~~~~~~~~~~~~~~~~~~^^^^^^^^^^^^^^^^^^^^^^^^^^
  File "C:\Users\JAIMIL KOTHARI\AppData\Roaming\Python\Python313\site-packages\mysql\connector\abstracts.py", line 1366, in set_charset_collation
    self._execute_query(f"SET NAMES '{charset_name}' COLLATE '{collation_name}'")
    ~~~~~~~~~~~~~~~~~~~^^^^^^^^^^^^^^^^^^^^^^^^^^^^^^^^^^^^^^^^^^^^^^^^^^^^^^^^^^
  File "C:\Users\JAIMIL KOTHARI\AppData\Roaming\Python\Python313\site-packages\mysql\connector\connection.py", line 1430, in _execute_query
    self.handle_unread_result()
    ~~~~~~~~~~~~~~~~~~~~~~~~~^^
  File "C:\Users\JAIMIL KOTHARI\AppData\Roaming\Python\Python313\site-packages\mysql\connector\connection.py", line 1740, in handle_unread_result
    raise InternalError("Unread result found")
mysql.connector.errors.InternalError: Unread result found

The above exception was the direct cause of the following exception:

Traceback (most recent call last):
  File "C:\Users\JAIMIL KOTHARI\AppData\Roaming\Python\Python313\site-packages\flask\app.py", line 1511, in wsgi_app
    response = self.full_dispatch_request()
  File "C:\Users\JAIMIL KOTHARI\AppData\Roaming\Python\Python313\site-packages\flask\app.py", line 919, in full_dispatch_request
    rv = self.handle_user_exception(e)
  File "C:\Users\JAIMIL KOTHARI\AppData\Roaming\Python\Python313\site-packages\flask_cors\extension.py", line 176, in wrapped_function
    return cors_after_request(app.make_response(f(*args, **kwargs)))
                                                ~^^^^^^^^^^^^^^^^^
  File "C:\Users\JAIMIL KOTHARI\AppData\Roaming\Python\Python313\site-packages\flask\app.py", line 917, in full_dispatch_request
    rv = self.dispatch_request()
  File "C:\Users\JAIMIL KOTHARI\AppData\Roaming\Python\Python313\site-packages\flask\app.py", line 902, in dispatch_request
    return self.ensure_sync(self.view_functions[rule.endpoint])(**view_args)  # type: ignore[no-any-return]
           ~~~~~~~~~~~~~~~~~~~~~~~~~~~~~~~~~~~~~~~~~~~~~~~~~~~~^^^^^^^^^^^^^
  File "C:\xampp\htdocs\Inbox\tripglide\backend\login.py", line 615, in flight_bookings
    db.reconnect()
    ~~~~~~~~~~~~^^
  File "C:\Users\JAIMIL KOTHARI\AppData\Roaming\Python\Python313\site-packages\mysql\connector\abstracts.py", line 1601, in reconnect
    raise InterfaceError(msg) from err
mysql.connector.errors.InterfaceError: Can not reconnect to MySQL after 1 attempt(s): Unread result found
2025-04-11 23:09:14,928 - ERROR - 500 GET /api/flight_bookings?user_id=44 (127.0.0.1) 19.93ms
2025-04-11 23:09:14,944 - DEBUG - Starting authorization phase
2025-04-11 23:09:14,944 - DEBUG - The provided initial strategy is mysql_native_password
2025-04-11 23:09:14,944 - DEBUG - mysql_native_password completed succesfully
2025-04-11 23:09:14,945 - ERROR - Exception on /api/profile [GET]
Traceback (most recent call last):
  File "C:\Users\JAIMIL KOTHARI\AppData\Roaming\Python\Python313\site-packages\mysql\connector\abstracts.py", line 1592, in reconnect
    self.connect()
    ~~~~~~~~~~~~^^
  File "C:\Users\JAIMIL KOTHARI\AppData\Roaming\Python\Python313\site-packages\mysql\connector\abstracts.py", line 1541, in connect
    self._post_connection()
    ~~~~~~~~~~~~~~~~~~~~~^^
  File "C:\Users\JAIMIL KOTHARI\AppData\Roaming\Python\Python313\site-packages\mysql\connector\abstracts.py", line 1481, in _post_connection
    self.set_charset_collation(charset=self._charset_id)
    ~~~~~~~~~~~~~~~~~~~~~~~~~~^^^^^^^^^^^^^^^^^^^^^^^^^^
  File "C:\Users\JAIMIL KOTHARI\AppData\Roaming\Python\Python313\site-packages\mysql\connector\abstracts.py", line 1366, in set_charset_collation
    self._execute_query(f"SET NAMES '{charset_name}' COLLATE '{collation_name}'")
    ~~~~~~~~~~~~~~~~~~~^^^^^^^^^^^^^^^^^^^^^^^^^^^^^^^^^^^^^^^^^^^^^^^^^^^^^^^^^^
  File "C:\Users\JAIMIL KOTHARI\AppData\Roaming\Python\Python313\site-packages\mysql\connector\connection.py", line 1430, in _execute_query
    self.handle_unread_result()
    ~~~~~~~~~~~~~~~~~~~~~~~~~^^
  File "C:\Users\JAIMIL KOTHARI\AppData\Roaming\Python\Python313\site-packages\mysql\connector\connection.py", line 1740, in handle_unread_result
    raise InternalError("Unread result found")
mysql.connector.errors.InternalError: Unread result found

The above exception was the direct cause of the following exception:

Traceback (most recent call last):
  File "C:\Users\JAIMIL KOTHARI\AppData\Roaming\Python\Python313\site-packages\flask\app.py", line 1511, in wsgi_app
    response = self.full_dispatch_request()
  File "C:\Users\JAIMIL KOTHARI\AppData\Roaming\Python\Python313\site-packages\flask\app.py", line 919, in full_dispatch_request
    rv = self.handle_user_exception(e)
  File "C:\Users\JAIMIL KOTHARI\AppData\Roaming\Python\Python313\site-packages\flask_cors\extension.py", line 176, in wrapped_function
    return cors_after_request(app.make_response(f(*args, **kwargs)))
                                                ~^^^^^^^^^^^^^^^^^
  File "C:\Users\JAIMIL KOTHARI\AppData\Roaming\Python\Python313\site-packages\flask\app.py", line 917, in full_dispatch_request
    rv = self.dispatch_request()
  File "C:\Users\JAIMIL KOTHARI\AppData\Roaming\Python\Python313\site-packages\flask\app.py", line 902, in dispatch_request
    return self.ensure_sync(self.view_functions[rule.endpoint])(**view_args)  # type: ignore[no-any-return]
           ~~~~~~~~~~~~~~~~~~~~~~~~~~~~~~~~~~~~~~~~~~~~~~~~~~~~^^^^^^^^^^^^^
  File "C:\xampp\htdocs\Inbox\tripglide\backend\login.py", line 464, in profile
    db.reconnect()
    ~~~~~~~~~~~~^^
  File "C:\Users\JAIMIL KOTHARI\AppData\Roaming\Python\Python313\site-packages\mysql\connector\abstracts.py", line 1601, in reconnect
    raise InterfaceError(msg) from err
mysql.connector.errors.InterfaceError: Can not reconnect to MySQL after 1 attempt(s): Unread result found
2025-04-11 23:09:14,951 - ERROR - 500 GET /api/profile?identifier=jaimilkothari2003%40gmail.com (127.0.0.1) 14.78ms
2025-04-11 23:09:14,967 - DEBUG - Starting authorization phase
2025-04-11 23:09:14,968 - DEBUG - The provided initial strategy is mysql_native_password
2025-04-11 23:09:14,969 - DEBUG - mysql_native_password completed succesfully
2025-04-11 23:09:14,970 - ERROR - Exception on /api/flight_bookings [GET]
Traceback (most recent call last):
  File "C:\Users\JAIMIL KOTHARI\AppData\Roaming\Python\Python313\site-packages\mysql\connector\abstracts.py", line 1592, in reconnect
    self.connect()
    ~~~~~~~~~~~~^^
  File "C:\Users\JAIMIL KOTHARI\AppData\Roaming\Python\Python313\site-packages\mysql\connector\abstracts.py", line 1541, in connect
    self._post_connection()
    ~~~~~~~~~~~~~~~~~~~~~^^
  File "C:\Users\JAIMIL KOTHARI\AppData\Roaming\Python\Python313\site-packages\mysql\connector\abstracts.py", line 1481, in _post_connection
    self.set_charset_collation(charset=self._charset_id)
    ~~~~~~~~~~~~~~~~~~~~~~~~~~^^^^^^^^^^^^^^^^^^^^^^^^^^
  File "C:\Users\JAIMIL KOTHARI\AppData\Roaming\Python\Python313\site-packages\mysql\connector\abstracts.py", line 1366, in set_charset_collation
    self._execute_query(f"SET NAMES '{charset_name}' COLLATE '{collation_name}'")
    ~~~~~~~~~~~~~~~~~~~^^^^^^^^^^^^^^^^^^^^^^^^^^^^^^^^^^^^^^^^^^^^^^^^^^^^^^^^^^
  File "C:\Users\JAIMIL KOTHARI\AppData\Roaming\Python\Python313\site-packages\mysql\connector\connection.py", line 1430, in _execute_query
    self.handle_unread_result()
    ~~~~~~~~~~~~~~~~~~~~~~~~~^^
  File "C:\Users\JAIMIL KOTHARI\AppData\Roaming\Python\Python313\site-packages\mysql\connector\connection.py", line 1740, in handle_unread_result
    raise InternalError("Unread result found")
mysql.connector.errors.InternalError: Unread result found

The above exception was the direct cause of the following exception:

Traceback (most recent call last):
  File "C:\Users\JAIMIL KOTHARI\AppData\Roaming\Python\Python313\site-packages\flask\app.py", line 1511, in wsgi_app
    response = self.full_dispatch_request()
  File "C:\Users\JAIMIL KOTHARI\AppData\Roaming\Python\Python313\site-packages\flask\app.py", line 919, in full_dispatch_request
    rv = self.handle_user_exception(e)
  File "C:\Users\JAIMIL KOTHARI\AppData\Roaming\Python\Python313\site-packages\flask_cors\extension.py", line 176, in wrapped_function
    return cors_after_request(app.make_response(f(*args, **kwargs)))
                                                ~^^^^^^^^^^^^^^^^^
  File "C:\Users\JAIMIL KOTHARI\AppData\Roaming\Python\Python313\site-packages\flask\app.py", line 917, in full_dispatch_request
    rv = self.dispatch_request()
  File "C:\Users\JAIMIL KOTHARI\AppData\Roaming\Python\Python313\site-packages\flask\app.py", line 902, in dispatch_request
    return self.ensure_sync(self.view_functions[rule.endpoint])(**view_args)  # type: ignore[no-any-return]
           ~~~~~~~~~~~~~~~~~~~~~~~~~~~~~~~~~~~~~~~~~~~~~~~~~~~~^^^^^^^^^^^^^
  File "C:\xampp\htdocs\Inbox\tripglide\backend\login.py", line 615, in flight_bookings
    db.reconnect()
    ~~~~~~~~~~~~^^
  File "C:\Users\JAIMIL KOTHARI\AppData\Roaming\Python\Python313\site-packages\mysql\connector\abstracts.py", line 1601, in reconnect
    raise InterfaceError(msg) from err
mysql.connector.errors.InterfaceError: Can not reconnect to MySQL after 1 attempt(s): Unread result found
2025-04-11 23:09:14,974 - ERROR - 500 GET /api/flight_bookings?user_id=44 (127.0.0.1) 10.91ms
2025-04-11 23:10:14,148 - INFO - C:\xampp\htdocs\Inbox\tripglide\backend\login.py modified; restarting server
